Workbook

Sheet Test Scenarios
A1: TEST SCENARIO FOR REGISTER UI
A2: ID | B2: TITLE | C2: SUMMARY | D2: PRE-CONDITION | E2: PRIOTY | F2: TEST TYPE | G2: EXPECTED RESULT
A3: TS-R-UI-001 | B3: Kiểm tra tính Responsive của Form Đăng Kí. | C3: ='Test Cases'!F4 -> Verify that the registration form is responsive across different devices and creen sizes. | D3: ='Test Cases'!G3 -> 1. Environment: The User accesses the web page through a supported browser (Egde). 2. Connect: The internet connection is stable. | E3: High | F3: UI/Usability | G3: ='Test Cases'!L4 -> The form and fields should resize well and show all content clearly.
A4: TS-R-UI-002 | B4: Đăng kí thông thành công với form trống. | C4: ='Test Cases'!F11 -> Verify the logic works correctly when the form is empty. | D4: ='Test Cases'!G11 -> 1.Status: The registration form has loaded. 2.Data: All fields are empty. | E4: High | F4: Functional | G4: ='Test Cases'!L11 -> The registration is unsuccessful and a notification displays "information is required, cant be empty"
A5: TS-R-UI-003 | B5: MSSV không hợp lệ. | C5: Người dùng nhập vào MSSV không hợp lệ (bỏ trống, đã tồn tại, sai định dạng, chứa kí tự đặc biệt_ | D5: ='Test Cases'!G12 -> 1. The GMAIL doesn't exist. 2. The system has constraint rules for MSSV: - Must not be empty. - Must not be duplicated - Can't contain special characters - Must be exactly 8 characters | E5: High | F5: Functional | G5: ='Test Cases'!L15 -> The registration is unsuccessful and a notification displays: "MSSV is invalid. A valid MSSV must have exactly 8 characters, cannot be empty, and cannot contain special characters"
A6: TS-R-UI-004 | B6: Gmail không hợp lệ. | C6: Người dùng nhập vào Gmail đã tồn tại. | D6: ='Test Cases'!G42 -> 1. MSSV & Gmail don't exist in the database. 2. The system has constraint rules for the "Gmail" field: - Gmail must be unique in the database. - Must not be empty. - Must be valid format. - Must not contain duplicated characters.. | E6: High | F6: Functional | G6: ='Test Cases'!L44 -> Đăng kí tài khoản không thành công và hiển thị thông báo “Gmail không hợp lệ.”
A7: TS-R-UI-005 | B7: Password không hợp lệ. | C7: Người dùng nhập vào Password không hợp lệ ( bỏ trống, sai số lượng kí tự) | D7: ='Test Cases'!G37 -> 1. MSSV & Gmail don't exist in the database. 2. The system has constraint rules for the "Password" field: - Must not be empty. - Password length must be within the allowed range (6 < length < 32). - Must not contain duplicated characters.. | E7: High | F7: Functional | G7: ='Test Cases'!L38 -> Đăng kí tài khoản không thành công và hiển thị thông báo “Password hợp lệ có độ dài từ 6-32 kí tự, không trùng lặp kí tự.”
A8: TS-R-UI-006 | B8: Lớp không hợp lệ. | C8: Người dùng nhập vào Lớp không hợp lệ (bỏ trống, chứa kí tự đặc biệt, số) | D8: ='Test Cases'!G29 -> 1. MSSV & Gmail don't exist in the database. 2. The system has constraint rules for the "Lớp" field: - Must not be empty. - Must not be contain special and number characters. - Each MSSV must correspond to a specific class. Example: MSSV CQT22513 → Class = Quản trị mạng máy tính. | E8: High | F8: Functional | G8: ='Test Cases'!L29 -> Đăng kí không thành công. Hiển thị thông báo "Lớp không hợp lệ, không được chứa kí tự số hoặc đặc biệt."
A9: TS-R-UI-007 | B9: Kiểm tra chức năng gửi dữ liệu của nút “Đăng kí” | C9: ='Test Cases'!F8 -> Verify if clicking the "Đăng Kí" button sends the form data. | D9: ='Test Cases'!G8 -> 1.Status: The registration form has loaded. 2.Data: Enter data in all fields. | E9: High | F9: Functional | G9: ='Test Cases'!L8 -> The "Đăng Kí" button works correctly. The user can send registration information to the Server.
A10: TS-R-UI-008 | B10: Kiểm tra tốc độ tải trang | C10: ='Test Cases'!F3 -> Verify that the webpage loads within acceptable time. | D10: ='Test Cases'!G3 -> 1. Environment: The User accesses the web page through a supported browser (Egde). 2. Connect: The internet connection is stable. | E10: Medium | F10: UI/Usability | G10: ='Test Cases'!L3 -> The maximum page load time should be 3-5 seconds.
A11: TS-R-UI-009 | B11: Kiểm tra thời gian gửi Request | C11: ='Test Cases'!F9 -> Verify how long the browser takes to send the registration request to the server. | D11: ='Test Cases'!G9 -> 1.Status: The registration form has loaded. 2.Data: All fields are filled with valid data and submission is successful. | E11: Medium | F11: UI/Usability | G11: ='Test Cases'!L9 -> The sending time should be less than 0.5 seconds
A12: TS-R-UI-010 | B12: Kiểm tra thời gian nhận Response | C12: ='Test Cases'!F10 -> Verify how long the server takes to process the registration request and send the response (200 OK or 400 Bad Request). | D12: ='Test Cases'!G10 -> 1.Status: The registration form has loaded. 2.Data: All fields are filled with valid data and submission is successful. | E12: High | F12: UI/Usability | G12: ='Test Cases'!L10 -> Waiting time (TTFB) < 1.5 seconds and > 0.5 seconds."
A13: TS-R-UI-011 | B13: Đăng kí thành công với thông tin hợp lệ. | C13: Người dùng nhập vào thông tin đăng kí hợp lệ và đăng kí thành công. | D13: ='Test Cases'!G46 -> All constraint rules for each fields are satisfied. | E13: High | F13: Functional | G13: ='Test Cases'!L46 -> 1. Đăng kí tài khoản thành công. 2. Hiển thị thông báo “Đăng kí thành công, đang chuyển hướng sang Đăng nhập. 3. Chuyển hướng sang trang Đăng nhập thành công.
A14: TS-R-UI-012 | B14: Kiểm tra hành vi chuyển hướng sau khi đăng ký thành công | C14: ='Test Cases'!F48 -> Verify the system auto redirection after successful registration | D14: ='Test Cases'!G48 -> 1. Đã đăng kí thành công tài khoản. 2. Kết nối Internet ổn định. | E14: Medium | F14: Functional | G14: ='Test Cases'!L48 -> Chuyển sang trang Đăng nhập thành công.

Sheet Test Cases
A1: TEST CASE FOR REGISTER UI
A2: ID | B2: CREATE BY | C2: CREATE DATE | D2: EXCUTE DATE | E2: TITLE | F2: SUMMARY | G2: PRE-CONDITON | H2: DEPENDENCIES | I2: PRIORITY | J2: TEST DATA | K2: TEST STEP | L2: EXPECTED RESULT | M2: ACTUAL RESULT | N2: STATUS
A3: TC_RES_UI_001 | B3: Ngọc Hân | C3: 45951 | E3: Check the page loading speed. | F3: Verify that the webpage loads within acceptable time. | G3: 1. Environment: The User accesses the web page through a supported browser (Egde). 2. Connect: The internet connection is stable. | H3: (none) | I3: High | J3: (none) | K3: 1. Open the browser and delete cache and history. 2. Navigate to localhost:5257/register.html. 3. Open Devtools (F12) and measure how long it takes from typing the URL until the page shows completely. | L3: The maximum page load time should be 3-5 seconds.
A4: TC_RES_UI_002 | B4: Ngọc Hân | C4: 45951 | E4: Check responsive for registration form | F4: Verify that the registration form is responsive across different devices and creen sizes. | G4: 1. Environment: The user accesses the web page through a supported browser (Egde) 2. Status: The registration form has loaded. | H4: =$A$3 -> TC_RES_UI_001 | I4: High | J4: (none) | K4: 1. Resize the browser window from the smallest to the largest size by dragging ít. 2. Open Devtools (F12) and choose mobile or tablet view to test the page. | L4: The form and fields should resize well and show all content clearly.
A5: TC_RES_UI_003 | B5: Ngọc Hân | C5: 45951 | E5: Check Tab order on different screen sizes. | F5: Người dùng đang focus vào trường MSSV. Nhấn phím Tab liên tiếp để chuyển focus qua các trường. | G5: 1. Status: The registration form has loaded. 2. Device: Use the keyboard (desktop/laptop) | H5: =$A$4 -> TC_RES_UI_002 | I5: Medium | J5: (none) | K5: 1. Đảm bảo focus ban đầu nằm ở trường nhập liệu đầu tiên (Ví dụ: MSSV). 2. Nhấn phím Tab liên tục từ đầu đến cuối form. | L5: Focus phải chuyển từ trường này sang trường kế tiếp theo thứ tự logic của form (MSSV -> Họ & Tên -> Lớp -> Khóa học... -> Đăng ký).
A6: TC_RES_UI_004 | B6: Ngọc Hân | C6: 45952 | E6: Check the password hide/unhide function. | F6: Test if the password field can show or hide text. | G6: 1. Status: The registration form has loaded. 2. Device: Use the keyboard (desktop/laptop)
A7: TC_RES_UI_005 | B7: Ngọc Hân | C7: 45951 | E7: Check the Password hide/unhide on mobile and desktop. | F7: Verify the Password fields can show or hide text on different screen sizes. | G7: 1.Status: The registration form has loaded. 2.Data: Enter data in Password field. | H7: =$A$4 -> TC_RES_UI_002 | I7: Medium | J7: Password: 654321 | K7: 1. Navigate to localhost:5257/register.html. 2. Enter password in the password field. 3. Check the default status of password field (hidden by default) 4. Click the "eye" icon to show the password. 5. Click the "eye" icon to hide the password. | L7: 1. Password is hidden by default. 2. Clicking the "eye" icon shows the password text. 3. Clicking again the "eye" icon hides the password text.
A8: TC_RES_UI_006 | B8: Ngọc Hân | C8: 45951 | E8: Check the submit data function by button "Đăng Kí" | F8: Verify if clicking the "Đăng Kí" button sends the form data. | G8: 1.Status: The registration form has loaded. 2.Data: Enter data in all fields. | H8: =$A$4 -> TC_RES_UI_002 | I8: Medium | J8: MSSV: CQT@22513 Họ & Tên: Nguyễn Ngọc Thanh Ngân. Năm sinh: 2008 Lớp: Quản Trị Mạng Máy Tính 2025. Khóa học: 2025 Password: 654321 Gmail: vann170723@gmail.com | K8: 1. Navigate to localhost:5257/register.html. 2. Enter data in all fields. 3. Click the "Đăng kí" button. | L8: The "Đăng Kí" button works correctly. The user can send registration information to the Server.
A9: TC_RES_UI_007 | B9: Ngọc Hân | C9: 45951 | E9: Check the request sending time. | F9: Verify how long the browser takes to send the registration request to the server. | G9: 1.Status: The registration form has loaded. 2.Data: All fields are filled with valid data and submission is successful. | H9: =$A$4 -> TC_RES_UI_002 | I9: Medium | J9: MSSV: CQT@22513 Họ & Tên: Nguyễn Ngọc Thanh Ngân. Năm sinh: 2008 Lớp: Quản Trị Mạng Máy Tính 2025. Khóa học: 2025 Password: 654321 Gmail: vann170723@gmail.com | K9: 1. Open Devtools, choose network tab. 2. All fields filled with valid data. 3. Click the "Đăng Kí" button. 4. Select the registration request API. 5. Look at the timing section. | L9: The sending time should be less than 0.5 seconds
A10: TC_RES_UI_008 | B10: Ngọc Hân | C10: 45951 | E10: Check the response waiting time. | F10: Verify how long the server takes to process the registration request and send the response (200 OK or 400 Bad Request). | G10: 1.Status: The registration form has loaded. 2.Data: All fields are filled with valid data and submission is successful. | H10: =$A$4 -> TC_RES_UI_002 | I10: High | J10: MSSV: CQT@22513 Họ & Tên: Nguyễn Ngọc Thanh Ngân. Năm sinh: 2008 Lớp: Quản Trị Mạng Máy Tính 2025. Khóa học: 2025 Password: 654321 Gmail: vann170723@gmail.com | K10: 1. Open Devtools, choose network tab. 2. All fields filled with valid data. 3. Click the "Đăng Kí" button. 4. Select the registration request API. 5. Look at the timing section. | L10: Waiting time (TTFB) < 1.5 seconds and > 0.5 seconds."
A11: TC_RES_UI_009 | B11: Ngọc Hân | C11: 45951 | E11: Check registration with the Form is empty. | F11: Verify the logic works correctly when the form is empty. | G11: 1.Status: The registration form has loaded. 2.Data: All fields are empty. | H11: (none) | I11: High | J11: (none) | K11: 1. Navigat to localhost:5257/register.html. 2. All fields are empty. 3. Click the "Đăng Kí" button. 4. Check that an error message is displayed | L11: The registration is unsuccessful and a notification displays "information is required, cant be empty"
A12: TC_RES_UI_010 | B12: Ngọc Hân | C12: 45968 | E12: Check registration with the "MSSV" is empty. | F12: Verify the logic works correctly when the leave required field emtpy (MSSV) | G12: 1. The GMAIL doesn't exist. 2. The system has constraint rules for MSSV: - Must not be empty. - Must not be duplicated - Can't contain special characters - Must be exactly 8 characters | H12: (none) | I12: High | J12: MSSV: (bỏ trống) Họ & Tên: Nguyễn Ngọc Thanh Ngân. Năm sinh: 2008 Lớp: Quản Trị Mạng Máy Tính. Khóa học: 2025 Password: 654321 Gmail: vann170723@gmail.com | K12: 1. Navigate to localhost:5257/register.html. 2. MSSV field is empty. 3. Enter valid information in the remaining fields using test data. 4. Click the "Đăng Kí" button. 5. Check that an error message is displayed | L12: The registration is unsuccessful and a notification displays "MSSV is required, can't be empty"
A13: TC_RES_UI_011 | B13: Ngọc Hân | C13: 45951 | E13: Check registration with the MSSV already exists in the system. | F13: Verify the system shows an error when MSSV already exists in the system. | G13: 1. The MSSV already exists & GMAIL doesn't exists in the Database. 2. The system has constraint rules for MSSV: - Must not be empty. - Must not be duplicated - Can't contain special characters - Must be exactly 8 characters | H13: (none) | I13: High | J13: MSSV: CQT22512 Họ & Tên: Nguyễn Ngọc Thanh Ngân. Năm sinh: 2008 Lớp: Quản Trị Mạng Máy Tính. Khóa học: 2025 Password: 654321 Gmail: vann170723@gmail.com | K13: 1. Navigate to localhost:5257/register.html. 2. Enter "CQT22512" in MSSV field from Test Data. 3. Enter valid information in the remaining fields using test data. 4. Click the "Đăng Kí" button. 5. Check that an error message is displayed | L13: The registration is unsuccessful and a notification displays: "MSSV is invalid. A valid MSSV must have exactly 8 characters, cannot be empty, and cannot contain special characters"
A14: TC_RES_UI_012 | B14: Ngọc Hân | C14: 45951 | E14: Check registration with the MSSV is longer than the allowed length. | F14: Verify the system shows an error when MSSV input is longer than 8 characters. | G14: 1. GMAIL doesn't exists in the database. 2. The system has constraint rules for MSSV: - Must not be empty. - Must not be duplicated - Can't contain special characters - Must be exactly 8 characters | H14: (none) | I14: High | J14: MSSV: CQT225133 Họ & Tên: Nguyễn Ngọc Thanh Ngân. Năm sinh: 2008 Lớp: Quản Trị Mạng Máy Tính. Khóa học: 2025 Password: 654321 Gmail: vann170723@gmail.com | K14: 1. Navigate to localhost:5257/register.html. 2. Enter "CQT225133" in MSSV field from Test Data. 3. Enter valid information in the remaining fields using test data. 4. Click the "Đăng Kí" button. 5. Check that an error message is displayed | L14: The registration is unsuccessful and a notification displays: "MSSV is invalid. A valid MSSV must have exactly 8 characters, cannot be empty, and cannot contain special characters"
A15: TC_RES_UI_013 | B15: Ngọc Hân | C15: 45951 | E15: Check registration with the MSSV is shorter than the allowed length. | F15: Verify the system shows an error when MSSV input is shorter than 8 characters. | G15: 1. GMAIL doesn't exists in the database. 2. The system has constraint rules for MSSV: - Must not be empty. - Must not be duplicated - Can't contain special characters - Must be exactly 8 characters | H15: (none) | I15: High | J15: MSSV: CQT225 Họ & Tên: Nguyễn Ngọc Thanh Ngân. Năm sinh: 2008 Lớp: Quản Trị Mạng Máy Tính. Khóa học: 2025 Password: 654321 Gmail: vann170723@gmail.com | K15: 1. Navigate to localhost:5257/register.html. 2. Enter "CQT225" in MSSV field from Test Data. 3. Enter valid information in the remaining fields using test data. 4. Click the "Đăng Kí" button. 5. Check that an error message is displayed | L15: The registration is unsuccessful and a notification displays: "MSSV is invalid. A valid MSSV must have exactly 8 characters, cannot be empty, and cannot contain special characters"
A16: TC_RES_UI_014 | B16: Ngọc Hân | C16: 45951 | E16: Check registration with the MSSV contains special characters | F16: Verify the system shows an error when MSSV input contains special characters. | G16: 1. GMAIL doesn't exists in the database. 2. The system has constraint rules for MSSV: - Must not be empty. - Must not be duplicated - Can't contain special characters - Must be exactly 8 characters | H16: (none) | I16: High | J16: MSSV: CQT@22513 Họ & Tên: Nguyễn Ngọc Thanh Ngân. Năm sinh: 2008 Lớp: Quản Trị Mạng Máy Tính. Khóa học: 2025 Password: 654321 Gmail: vann170723@gmail.com | K16: 1. Navigate to localhost:5257/register.html. 2. Enter "CQT@22513" in MSSV field from Test Data. 3. Enter valid information in the remaining fields using test data. 4. Click the "Đăng Kí" button. 5. Check that an error message is displayed | L16: Đăng kí tài khoản không thành công và hiển thị thông báo “MSSV không hợp lệ. MSSV hợp lệ có độ dài 8-9 kí tự, không chứa kí tự đặc biệt.”
A17: TC_RES_UI_015 | B17: Ngọc Hân | C17: 45951 | E17: Check registration with the MSSV is valid | F17: Verify the system accepts registration successful when MSSV is valid | G17: 1. MSSV & GMAIL don't exists in the database. 2. The system has constraint rules for MSSV: - Must not be empty. - Must not be duplicated - Can't contain special characters - Must be exactly 8 characters | H17: (none) | I17: High | J17: MSSV: CQT22513 Họ & Tên: Nguyễn Ngọc Thanh Ngân. Năm sinh: 2008 Lớp: Quản Trị Mạng Máy Tính. Khóa học: 2025 Password: 654321 Gmail: vann170723@gmail.com | K17: 1. Navigate to localhost:5257/register.html. 2. Enter "CQT22513" in MSSV field from Test Data. 3. Enter valid information in the remaining fields using test data. 4. Click the "Đăng Kí" button. | L17: MSSV hợp lệ, đủ điều kiện đăng kí thành công.
A18: TC_RES_UI_016 | B18: Ngọc Hân | C18: 45968 | E18: Check registration with the "Họ & Tên" field is empty | F18: Verify the system shows an error when the "Họ & Tên" field is empty . | G18: 1. MSSV & Gmail don't exist in the database. 2. The system has constraint rules for the "Họ & Tên" field: - Must not be empty. - Must contain a full name. - Can't contain special characters. | H18: (none) | I18: High | J18: MSSV: CQT22513 Họ & Tên: (bỏ trống) Năm sinh: 2008 Lớp: Quản Trị Mạng Máy Tính. Khóa học: 2025 Password: 654321 Gmail: vann170723@gmail.com | K18: 1. Navigate to localhost:5257/register.html. 2. The "Họ & Tên" field is empty. 3. Enter valid information in the remaining fields using test data. 4. Click the "Đăng Kí" button. 5. Check that an error message is displayed | L18: Đăng kí tài khoản không thành công và hiển thị thông báo “Họ & Tên không được bỏ trống”
A19: TC_RES_UI_017 | B19: Ngọc Hân | C19: 45951 | E19: Check registration when the "Họ & Tên" field contains only surname | F19: Verify the system shows an error when the "Họ & Tên" input contains only surname. | G19: 1. MSSV & Gmail don't exist in the database. 2. The system has constraint rules for the "Họ & Tên" field: - Must not be empty. - Must contain a full name. - Can't contain special characters. | H19: (none) | I19: High | J19: MSSV: CQT22513 Họ & Tên: Nguyễn. Năm sinh: 2008 Lớp: Quản Trị Mạng Máy Tính. Khóa học: 2025 Password: 654321 Gmail: vann170723@gmail.com | K19: 1. Navigate to localhost:5257/register.html. 2. Enter "Nguyễn" in Họ & Tên field from Test Data. 3. Enter valid information in the remaining fields using test data. 4. Click the "Đăng Kí" button. 5. Check that an error message is displayed. | L19: Đăng kí tài khoản không thành công và hiển thị thông báo “Họ & Tên không hơp lệ. Thông tin hợp lệ bao gồm đầy đủ Họ và Tên, không chứa kí tự đặc biệt hoặc số.”
A20: TC_RES_UI_018 | B20: Ngọc Hân | C20: 45951 | E20: Check registration when the "Họ & Tên" field contains only firstname. | F20: Verify the system shows an error when the "Họ & Tên" input contains only firstname. | G20: 1. MSSV & Gmail don't exist in the database. 2. The system has constraint rules for the "Họ & Tên" field: - Must not be empty. - Must contain a full name. - Can't contain special characters. | H20: (none) | I20: High | J20: MSSV: CQT22513 Họ & Tên: Ngân. Năm sinh: 2008 Lớp: Quản Trị Mạng Máy Tính. Khóa học: 2025 Password: 654321 Gmail: vann170723@gmail.com | K20: 1. Navigate to localhost:5257/register.html. 2. Enter "Ngân" in Họ & Tên field from Test Data. 3. Enter valid information in the remaining fields using test data. 4. Click the "Đăng Kí" button. 5. Check that an error message is displayed. | L20: Đăng kí tài khoản không thành công và hiển thị thông báo “Họ & Tên không hơp lệ. Thông tin hợp lệ bao gồm đầy đủ Họ và Tên, không chứa kí tự đặc biệt hoặc số.”
A21: TC_RES_UI_019 | B21: Ngọc Hân | C21: 45951 | E21: Check registration when the "Họ & Tên" field contains special characters. | F21: Verify the system shows an error when the "Họ & Tên" input contains special chacracters. | G21: 1. MSSV & Gmail don't exist in the database. 2. The system has constraint rules for the "Họ & Tên" field: - Must not be empty. - Must contain a full name. - Can't contain special characters. | H21: (none) | I21: High | J21: MSSV: CQT22513 Họ & Tên: Nguyễn_Ngọc_Thanh_Ngân@CQT. Năm sinh: 2008 Lớp: Quản Trị Mạng Máy Tính. Khóa học: 2025 Password: 654321 Gmail: vann170723@gmail.com | K21: 1. Navigate to localhost:5257/register.html. 2. Enter "Nguyễn_Ngọc_Thanh_Ngân@CQT" in Họ & Tên field from Test Data. 3. Enter valid information in the remaining fields using test data. 4. Click the "Đăng Kí" button. 5. Check that an error message is displayed. | L21: Đăng kí tài khoản không thành công và hiển thị thông báo “Họ & Tên không hơp lệ. Thông tin hợp lệ bao gồm đầy đủ Họ và Tên, không chứa kí tự đặc biệt hoặc số.”
A22: TC_RES_UI_020 | B22: Ngọc Hân | C22: 45951 | E22: Check registration when the"Họ & Tên" field contains number characters . | F22: Verify the system shows an error when the "Họ & Tên" input contains number chacracters. | G22: 1. MSSV & Gmail don't exist in the database. 2. The system has constraint rules for the "Họ & Tên" field: - Must not be empty. - Must contain a full name. - Can't contain special characters. | H22: (none) | I22: High | J22: MSSV: CQT22513 Họ & Tên: Nguyễn Ngọc Thanh Ngân 2k8. Năm sinh: 2008 Lớp: Quản Trị Mạng Máy Tính. Khóa học: 2025 Password: 654321 Gmail: vann170723@gmail.com | K22: 1. Navigate to localhost:5257/register.html. 2. Enter "Nguyễn Ngọc Thanh Ngân 2k8" in Họ & Tên field from Test Data. 3. Enter valid information in the remaining fields using test data. 4. Click the "Đăng Kí" button. 5. Check that an error message is displayed. | L22: Đăng kí tài khoản không thành công và hiển thị thông báo “Họ & Tên không hơp lệ. Thông tin hợp lệ bao gồm đầy đủ Họ và Tên, không chứa kí tự đặc biệt hoặc số.”
A23: TC_RES_UI_021 | B23: Ngọc Hân | C23: 45951 | E23: Check registration with the "Họ & Tên" field is valid. | F23: Verify the system accepts registration successful when "Họ & Tên" is valid | G23: 1. MSSV & Gmail don't exist in the database. 2. The system has constraint rules for the "Họ & Tên" field: - Must not be empty. - Must contain a full name. - Can't contain special characters. | H23: (none) | I23: High | J23: MSSV: CQT@22513 Họ & Tên: Nguyễn Ngọc Thanh Ngân. Năm sinh: 2008 Lớp: Quản Trị Mạng Máy Tính. Khóa học: 2025 Password: 654321 Gmail: vann170723@gmail.com | K23: 1. Navigate to localhost:5257/register.html. 2. Enter "Nguyễn Ngọc Thanh Ngân" in Họ & Tên field from Test Data. 3. Enter valid information in the remaining fields using test data. 4. Click the "Đăng Kí" button. | L23: Họ & Tên hợp lệ, đủ điều kiện đăng kí thành công.
A24: TC_RES_UI_022 | C24: 45968 | E24: Check registration when the "Năm Sinh" field is empty. | F24: Verify the system shows an error when the "Năm Sinh" field is empty . | G24: 1. MSSV & Gmail don't exist in the database. 2. The system has constraint rules for the "Năm Sinh" field: - Must not be empty. - Must not be contain special and text characters. - Birth year must match the expected age for the chosen course. - Example: For "Khoá Học: 2025" (starting in 2025), the "Năm Sinh" must be 2007. | H24: (none) | I24: High | J24: MSSV: CQT22513 Họ & Tên: Nguyễn Ngọc Thanh Ngân. Năm sinh: (bỏ trống) Lớp: Quản Trị Mạng Máy Tính. Khóa học: 2025 Password: 654321 Gmail: vann170723@gmail.com | K24: 1. Navigate to localhost:5257/register.html. 2. The "Năm Sinh" field is empty. 3. Enter valid information in the remaining fields using test data. 4. Click the "Đăng Kí" button. 5. Check that an error message is displayed. | L24: Đăng kí tài khoản không thành công và hiển thị thông báo “Năm Sinh không được bỏ trống”
A25: TC_RES_UI_023 | B25: Ngọc Hân | C25: 45951 | E25: Check registration when the "Năm Sinh" field doesn't match "Khoá Học" field. | F25: Verify the system shows an error when the "Năm Sinh" field input doesn't match "Khoá Học" | G25: 1. MSSV & Gmail don't exist in the database. 2. The system has constraint rules for the "Năm Sinh" field: - Must not be empty. - Must not be contain special and text characters. - Birth year must match the expected age for the chosen course. - Example: For "Khoá Học: 2025" (starting in 2025), the "Năm Sinh" must be 2007. | H25: =$A$36 -> TC_RES_UI_033 | I25: High | J25: MSSV: CQT@22513 Họ & Tên: Nguyễn Ngọc Thanh Ngân. Năm sinh: 2009 Lớp: Quản Trị Mạng Máy Tính. Khóa học: 2025 Password: 654321 Gmail: vann170723@gmail.com | K25: 1. Navigate to localhost:5257/register.html. 2. Enter "2009" in "Năm Sinh" field from Test Data. 3. Enter valid information in the remaining fields using test data. 4. Click the "Đăng Kí" button. 5. Check that an error message is displayed. | L25: Đăng kí không thành công. Hiển thị thông báo "Năm sinh không hợp lệ hoặc không khớp với Khóa học đã chọn."
A26: TC_RES_UI_024 | B26: Ngọc Hân | C26: 45951 | E26: Check registration with the "Năm Sinh" field is valid. | F26: Verify the system accepts registration successful when "Năm Sinh" is valid | G26: 1. MSSV & Gmail don't exist in the database. 2. The system has constraint rules for the "Năm Sinh" field: - Must not be empty. - Must not be contain special and text characters. - Birth year must match the expected age for the chosen course. - Example: For "Khoá Học: 2025" (starting in 2025), the "Năm Sinh" must be 2007. | H26: =$A$36 -> TC_RES_UI_033 | I26: High | J26: MSSV: CQT@22513 Họ & Tên: Nguyễn Ngọc Thanh Ngân. Năm sinh: 2008 Lớp: Quản Trị Mạng Máy Tính. Khóa học: 2025 Password: 654321 Gmail: vann170723@gmail.com | K26: 1. Navigate to localhost:5257/register.html. 2. Enter "2008" in "Năm Sinh" field from Test Data. 3. Enter valid information in the remaining fields using test data. 4. Click the "Đăng Kí" button. | L26: Năm Sinh hợp lệ, đủ điều kiện đăng kí thành công.
A27: TC_RES_UI_025 | B27: Ngọc Hân | C27: 45968 | E27: Check registration with the "Lớp" field is empty. | F27: Verify the system shows an error when the "Lớp" field is empty . | G27: 1. MSSV & Gmail don't exist in the database. 2. The system has constraint rules for the "Lớp" field: - Must not be empty. - Must not be contain special and number characters. - Each MSSV must correspond to a specific class. Example: MSSV CQT22513 → Class = Quản trị mạng máy tính. | H27: (none) | I27: High | J27: MSSV: CQT22513 Họ & Tên: Nguyễn Ngọc Thanh Ngân. Năm sinh: 2008 Lớp: (bỏ trống) Khóa học: 2025 Password: 654321 Gmail: vann170723@gmail.com | K27: 1. Navigate to localhost:5257/register.html. 2. The "Lớp" field is empty. 3. Enter valid information in the remaining fields using test data. 4. Click the "Đăng Kí" button. 5. Check that an error message is displayed. | L27: Đăng kí tài khoản không thành công và hiển thị thông báo “Lớp không được bỏ trống”
A28: TC_RES_UI_026 | B28: Ngọc Hân | C28: 45951 | E28: Check registration when the "Lớp" field contains number character. | F28: Verify the system shows an error when the "Lớp" input contains number characters . | G28: 1. MSSV & Gmail don't exist in the database. 2. The system has constraint rules for the "Lớp" field: - Must not be empty. - Must not be contain special and number characters. - Each MSSV must correspond to a specific class. Example: MSSV CQT22513 → Class = Quản trị mạng máy tính. | H28: (none) | I28: High | J28: MSSV: CQT@22513 Họ & Tên: Nguyễn Ngọc Thanh Ngân. Năm sinh: 2008 Lớp: Quản Trị Mạng Máy Tính 2025. Khóa học: 2025 Password: 654321 Gmail: vann170723@gmail.com | K28: 1. Navigate to localhost:5257/register.html. 2. Enter "Quản Trị Mạng Máy Tính 2025" in the "Lớp" from the Test Data. 3. Enter valid information in the remaining fields using test data. 4. Click the "Đăng Kí" button. 5. Check that an error message is displayed. | L28: Đăng kí không thành công. Hiển thị thông báo "Lớp không hợp lệ, không được chứa kí tự số hoặc đặc biệt."
A29: TC_RES_UI_027 | B29: Ngọc Hân | C29: 45951 | E29: Check registration when the "Lớp" field contains special character. | F29: Verify the system shows an error when the "Lớp" input contains special characters . | G29: 1. MSSV & Gmail don't exist in the database. 2. The system has constraint rules for the "Lớp" field: - Must not be empty. - Must not be contain special and number characters. - Each MSSV must correspond to a specific class. Example: MSSV CQT22513 → Class = Quản trị mạng máy tính. | H29: (none) | I29: High | J29: MSSV: CQT@22513 Họ & Tên: Nguyễn Ngọc Thanh Ngân. Năm sinh: 2008 Lớp: @Quản Trị Mạng Máy Tính Khóa học: 2025 Password: 654321 Gmail: vann170723@gmail.com | K29: 1. Navigate to localhost:5257/register.html. 2. Enter "@Quản Trị Mạng Máy Tính 2025" in the "Lớp" from the Test Data. 3. Enter valid information in the remaining fields using test data. 4. Click the "Đăng Kí" button. 5. Check that an error message is displayed. | L29: Đăng kí không thành công. Hiển thị thông báo "Lớp không hợp lệ, không được chứa kí tự số hoặc đặc biệt."
A30: TC_RES_UI_028 | B30: Ngọc Hân | C30: 45951 | E30: Check registration when the "Lớp" field doesn’t match "MSSV" field. | F30: Verify the system shows an error when the "Lớp" field doesn't match "MSSV" field. | G30: 1. MSSV & Gmail don't exist in the database. 2. The system has constraint rules for the "Lớp" field: - Must not be empty. - Must not be contain special and number characters. - Each MSSV must correspond to a specific class. Example: MSSV CQT22513 → Class = Quản trị mạng máy tính. | H30: =$A$17 -> TC_RES_UI_015 | I30: High | J30: MSSV: CQT@22513 Họ & Tên: Nguyễn Ngọc Thanh Ngân. Năm sinh: 2008 Lớp: Lắp ráp cài đặt Máy Tính Khóa học: 2025 Password: 654321 Gmail: vann170723@gmail.com | K30: 1. Navigate to localhost:5257/register.html. 2. Enter "Lắp ráp cài đặt Máy Tính Khóa" in the "Lớp" from the Test Data. 3. Enter valid information in the remaining fields using test data. 4. Click the "Đăng Kí" button. 5. Check that an error message is displayed. | L30: Đăng kí không thành công. Hiển thị thông báo "Lớp không hợp lệ, không được chứa kí tự số hoặc đặc biệt."
A31: TC_RES_UI_029 | B31: Ngọc Hân | C31: 45951 | E31: Check registration with the "Lớp" field is valid. | F31: Verify the system accepts registration successful when "Lớp" is valid | G31: 1. MSSV & Gmail don't exist in the database. 2. The system has constraint rules for the "Lớp" field: - Must not be empty. - Must not be contain special and number characters. - Each MSSV must correspond to a specific class. Example: MSSV CQT22513 → Class = Quản trị mạng máy tính. | H31: =$A$17 -> TC_RES_UI_015 | I31: High | J31: MSSV: CQT@22513 Họ & Tên: Nguyễn Ngọc Thanh Ngân. Năm sinh: 2008 Lớp: Quản Trị Mạng Máy Tính . Khóa học: 2025 Password: 654321 Gmail: vann170723@gmail.com | K31: 1. Navigate to localhost:5257/register.html. 2. Enter "Quản Trị Mạng Máy Tính" in the "Lớp" from the Test Data. 3. Enter valid information in the remaining fields using test data. 4. Click the "Đăng Kí" button. | L31: Lớp hợp lệ, đủ điều kiện đăng kí thành công.
A32: TC_RES_UI_030 | B32: Ngọc Hân | C32: 45968 | E32: Check registration with the "Khoá Học" field is empty. | F32: Verify the system shows an error when the "Khoá Học" field is empty . | G32: 1. MSSV & Gmail don't exist in the database. 2. The system has constraint rules for the "Năm Sinh" field: - Must not be empty. - Must not be contain special and text characters. - Birth year must match the expected age for the chosen course. - Example: For "Khoá Học: 2025" (starting in 2025), the "Năm Sinh" must be 2007. | H32: (none) | I32: High | J32: MSSV: CQT22513 Họ & Tên: Nguyễn Ngọc Thanh Ngân. Năm sinh: 2008 Lớp: Quản Trị Mạng Máy Tính. Khóa học: (bỏ trống) Password: 654321 Gmail: vann170723@gmail.com | K32: 1. Navigate to localhost:5257/register.html. 2. The "Khoá Học" field is empty. 3. Enter valid information in the remaining fields using test data. 4. Click the "Đăng Kí" button. 5. Check that an error message is displayed. | L32: Đăng kí tài khoản không thành công và hiển thị thông báo “Khóa học không được bỏ trống”
A33: TC_RES_UI_031 | B33: Ngọc Hân | C33: 45951 | E33: Check registration when the "Khoá Học" field contains text characters. | F33: Verify the system shows an error when the "Khoá Học" field contains text characters. | G33: 1. MSSV & Gmail don't exist in the database. 2. The system has constraint rules for the "Năm Sinh" field: - Must not be empty. - Must not be contain special and text characters. - The "Năm Sinh" field must match the expected age for the chosen the "Khoá Học" and "MSSV" field. - Example: For "Khoá Học: 2025" (starting in 2025), the "Năm Sinh" must be 2007. | H33: (none) | I33: High | J33: MSSV: CQT@22513 Họ & Tên: Nguyễn Ngọc Thanh Ngân. Năm sinh: 2008 Lớp: Quản Trị Mạng Máy Tính 2025. Khóa học: k2025 Password: 654321 Gmail: vann170723@gmail.com | K33: 1. Navigate to localhost:5257/register.html. 2. Enter "k2025" in the "Khoá Học" from Test Data. 3. Enter valid information in the remaining fields using test data. 4. Click the "Đăng Kí" button. 5. Check that an error message is displayed. | L33: Đăng kí tài khoản không thành công và hiển thị thông báo “Khoá Học không hợp lệ, vui lòng kiểm tra lại.”
A34: TC_RES_UI_032 | B34: Ngọc Hân | C34: 45951 | E34: Check registration when the "Khoá Học" field doesn't macth "MSSV" field. | F34: Verify the system shows an error when the "Khoá Học" field doesn't match "MSSV" field. | G34: 1. MSSV & Gmail chưa tồn tại trong DB. 2. Hệ thống có quy tắc ràng buộc Khoá Học (không bỏ trống, đúng quy tắc, định dạng) | H34: =$A$17 -> TC_RES_UI_015 | I34: High | J34: MSSV: CQT@22513 Họ & Tên: Nguyễn Ngọc Thanh Ngân. Năm sinh: 2008 Lớp: Quản Trị Mạng Máy Tính 2025. Khóa học: 2024 Password: 654321 Gmail: vann170723@gmail.com | K34: 1. Navigate to localhost:5257/register.html. 2. Enter "2024" in the "Khoá Học" from Test Data. 3. Enter valid information in the remaining fields using test data. 4. Click the "Đăng Kí" button. 5. Check that an error message is displayed. | L34: Đăng kí tài khoản không thành công và hiển thị thông báo “Khoá Học không hợp lệ, vui lòng kiểm tra lại.”
E35: Check registration when the "Khoá Học" field doesn't macth "Năm Sinh" field. | F35: Verify the system shows an error when the "Khoá Học" field doesn't match "Năm Sinh" field.
A36: TC_RES_UI_033 | B36: Ngọc Hân | C36: 45951 | E36: Check registration with "Khoá Học" field is valid. | F36: Verify the system accepts registration successful when "Khoá Học" field is valid | G36: 1. MSSV & Gmail chưa tồn tại trong DB. 2. Hệ thống có quy tắc ràng buộc Khoá Học (không bỏ trống, đúng quy tắc, định dạng) | H36: =$A$17 -> TC_RES_UI_015 | I36: High | J36: MSSV: CQT@22513 Họ & Tên: Nguyễn Ngọc Thanh Ngân. Năm sinh: 2008 Lớp: Quản Trị Mạng Máy Tính 2025. Khóa học: 2025 Password: 654321 Gmail: vann170723@gmail.com | K36: 1. Navigate to localhost:5257/register.html. 2. Enter "2025" in the "Khoá Học" from Test Data. 3. Enter valid information in the remaining fields using test data. 4. Click the "Đăng Kí" button. | L36: Khoá Học hợp lệ, đủ điều kiện đăng kí thành công.
A37: TC_RES_UI_034 | B37: Ngọc Hân | C37: 45968 | E37: Check registration with "Password" field is empty. | F37: Verify the system shows an error when the "Password" field is empty . | G37: 1. MSSV & Gmail don't exist in the database. 2. The system has constraint rules for the "Password" field: - Must not be empty. - Password length must be within the allowed range (6 < length < 32). - Must not contain duplicated characters.. | H37: (none) | I37: High | J37: MSSV: CQT@22513 Họ & Tên: Nguyễn Ngọc Thanh Ngân. Năm sinh: 2008 Lớp: Quản Trị Mạng Máy Tính 2025. Khóa học: 2025 Password: (bỏ trống) Gmail: vann170723@gmail.com | K37: 1. Navigate to localhost:5257/register.html. 2. The "Password" field is empty. 3. Enter valid information in the remaining fields using test data. 4. Click the "Đăng Kí" button. 5. Check that an error message is displayed. | L37: Đăng kí tài khoản không thành công và hiển thị thông báo “Password không được bỏ trống”
A38: TC_RES_UI_035 | B38: Ngọc Hân | C38: 45951 | E38: Check registration when the "Password" field is shorter than the allowed length. | F38: Verify the system shows an error when the "Password" field is shorter than the allowed length (<6) | G38: 1. MSSV & Gmail don't exist in the database. 2. The system has constraint rules for the "Password" field: - Must not be empty. - Password length must be within the allowed range (6 < length < 32). - Must not contain duplicated characters.. | H38: (none) | I38: High | J38: MSSV: CQT@22513 Họ & Tên: Nguyễn Ngọc Thanh Ngân. Năm sinh: 2008 Lớp: Quản Trị Mạng Máy Tính 2025. Khóa học: 2025 Password: 65432 Gmail: vann170723@gmail.com | K38: 1. Navigate to localhost:5257/register.html. 2. Enter "65432" in the "Password" field from Test Data. 3. Enter valid information in the remaining fields using test data. 4. Click the "Đăng Kí" button. 5. Check that an error message is displayed. | L38: Đăng kí tài khoản không thành công và hiển thị thông báo “Password hợp lệ có độ dài từ 6-32 kí tự, không trùng lặp kí tự.”
A39: TC_RES_UI_036 | B39: Ngọc Hân | C39: 45968 | E39: Check registration when the "Password" field is longer than the allowed length. | F39: Verify the system shows an error when the "Password" field is longer than the allowed length (>32) | G39: 1. MSSV & Gmail don't exist in the database. 2. The system has constraint rules for the "Password" field: - Must not be empty. - Password length must be within the allowed range (6 < length < 32). - Must not contain duplicated characters.. | H39: (none) | I39: Medium | J39: MSSV: CQT@22513 Họ & Tên: Nguyễn Ngọc Thanh Ngân. Năm sinh: 2008 Lớp: Quản Trị Mạng Máy Tính 2025. Khóa học: 2025 Password: 65432654326543265432 Gmail: vann170723@gmail.com | K39: 1. Navigate to localhost:5257/register.html. 2. Enter "65432654326543265432" in the "Password" field from Test Data. 3. Enter valid information in the remaining fields using test data. 4. Click the "Đăng Kí" button. 5. Check that an error message is displayed. | L39: Password hợp lệ, đủ điều kiện đăng kí thành công.
A40: TC_RES_UI_037 | B40: Ngọc Hân | C40: 45951 | E40: Check registration when the "Password" field is greater than the minimum but doesn't exceed maximum | F40: Verify the system accepts registration when the password length is within the allowed range (6 < length < 32). | G40: 1. MSSV & Gmail don't exist in the database. 2. The system has constraint rules for the "Password" field: - Must not be empty. - Password length must be within the allowed range (6 < length < 32). - Must not contain duplicated characters.. | H40: (none) | I40: High | J40: MSSV: CQT@22513 Họ & Tên: Nguyễn Ngọc Thanh Ngân. Năm sinh: 2008 Lớp: Quản Trị Mạng Máy Tính 2025. Khóa học: 2025 Password: 65432654326543265432654326543265432 Gmail: vann170723@gmail.com | K40: 1. Navigate to localhost:5257/register.html. 2. Enter "65432654326543265432654326543265432" in the "Password" field from Test Data. 3. Enter valid information in the remaining fields using test data. 4. Click the "Đăng Kí" button. 5. Check that an error message is displayed. | L40: Đăng kí tài khoản không thành công và hiển thị thông báo “Password hợp lệ có độ dài từ 6-32 kí tự, không trùng lặp kí tự.”
...

Sheet Defects Report
A1: BUG REPORTS - REGISTER UI
A2: DEFECT ID | B2: DESCRIPTION | C2: VERSION | D2: STEPS | E2: CREATE DATE | F2: FILE | G2: CREATE BY | H2: STATUS | I2: FIXED BY | J2: CLOSE DATE | K2: SERVERITY | L2: PRIORITY
